<?xml version="1.0"?>
<robot xmlns:xacro="http://www.ros.org/wiki/xacro"  name="robot">

    <xacro:include filename="inertial_macros.xacro"/>

    <material name="white">
        <color rgba="1 1 1 1"/>
    </material>

    <material name="orange">
        <color rgba="1 0.3 0.1 1"/>
    </material>

    <!-- BASE LINK -->

    <link name="base_link">

    </link>

    <joint name="base_footprint_joint" type="fixed">
        <parent link="base_link"/>
        <child link = "base_footprint"/>
        <origin xyz="0 0 0"/>
    </joint>

    <link name="base_footprint">
    </link>

    <!-- CHASSIS LINK -->

    <joint name="chassis_joint" type="fixed">
        <parent link="base_link"/>
        <child link = "chassis"/>
        <origin xyz="-0.114 0 0"/>
    </joint>

    <link name="chassis">
        <visual>
            <origin xyz="0.1145 0 0.07"/>
            <geometry>
                <box size="0.229 0.102 0.14"/>
            </geometry>
            <material name = "white"/>
        </visual>
        <collision>
            <origin xyz="0.1145 0 0.07"/>
            <geometry>
                <box size="0.229 0.102 0.14"/>
            </geometry>
        </collision>
        <xacro:inertial_box mass="0.453" x="0.229" y="0.102" z="0.14">
            <origin xyz="0.1145 0 0.07" rpy= "0 0 0"/>
        </xacro:inertial_box>
    </link>

    <!-- LEFT BACK WHEEL LINK -->

    <joint name="left_back_wheel_joint" type="continuous">
        <parent link="base_link"/>
        <child link="left_back_wheel"/>
        <origin xyz="-0.114 0.07 0" rpy="-${pi/2} 0 0"/>
        <axis xyz= "0 0 1"/>
    </joint>

    <link name="left_back_wheel">
        <visual>
            <geometry>
                <cylinder radius="0.025" length="0.038"/>
            </geometry>
            <material name = "white"/>
        </visual>
        <collision>
            <geometry>
                <cylinder radius="0.025" length="0.038"/>
            </geometry>
        </collision>
        <xacro:inertial_cylinder mass="0.1" length="0.038" radius="0.025">
            <origin xyz="0 0 0" rpy= "0 0 0"/>
        </xacro:inertial_cylinder>
    </link>

    <!-- LEFT FRONT WHEEL LINK -->

    <joint name="left_front_wheel_joint" type="continuous">
        <parent link="base_link"/>
        <child link="left_front_wheel"/>
        <origin xyz="0.114 0.07 0" rpy="-${pi/2} 0 0"/>
        <axis xyz= "0 0 1"/>
    </joint>

    <link name="left_front_wheel">
        <visual>
            <geometry>
                <cylinder radius="0.025" length="0.038"/>
            </geometry>
            <material name = "white"/>
        </visual>
        <collision>
            <geometry>
                <cylinder radius="0.025" length="0.038"/>
            </geometry>
        </collision>
        <xacro:inertial_cylinder mass="0.1" length="0.038" radius="0.025">
            <origin xyz="0 0 0" rpy= "0 0 0"/>
        </xacro:inertial_cylinder>
    </link>

    <gazebo reference="left_front_wheel">
        <mu1 value="0.001"/>
        <mu2 value="0.001"/>
    </gazebo>

    <!-- RIGHT BACK WHEEL LINK -->

    <joint name="right_back_wheel_joint" type="continuous">
        <parent link="base_link"/>
        <child link="right_back_wheel"/>
        <origin xyz="-0.114 -0.07 0" rpy="${pi/2} 0 0"/>
        <axis xyz= "0 0 -1"/>
    </joint>

    <link name="right_back_wheel">
        <visual>
            <geometry>
                <cylinder radius="0.025" length="0.038"/>
            </geometry>
            <material name = "white"/>
        </visual>
        <collision>
            <geometry>
                <cylinder radius="0.025" length="0.038"/>
            </geometry>
        </collision>
        <xacro:inertial_cylinder mass="0.1" length="0.038" radius="0.025">
            <origin xyz="0 0 0" rpy= "0 0 0"/>
        </xacro:inertial_cylinder>
    </link>

    <!-- RIGHT FORWARD WHEEL LINK -->

    <joint name="right_front_wheel_joint" type="continuous">
        <parent link="base_link"/>
        <child link="right_front_wheel"/>
        <origin xyz="0.114 -0.07 0" rpy="${pi/2} 0 0"/>
        <axis xyz= "0 0 -1"/>
    </joint>

    <link name="right_front_wheel">
        <visual>
            <geometry>
                <cylinder radius="0.025" length="0.038"/>
            </geometry>
            <material name = "white"/>
        </visual>
        <collision>
            <geometry>
                <cylinder radius="0.025" length="0.038"/>
            </geometry>
        </collision>
        <xacro:inertial_cylinder mass="0.1" length="0.038" radius="0.025">
            <origin xyz="0 0 0" rpy= "0 0 0"/>
        </xacro:inertial_cylinder>
    </link>

    <gazebo reference="right_front_wheel">
        <mu1 value="0.001"/>
        <mu2 value="0.001"/>
    </gazebo>
</robot>